Workbook
Name 在外公館リスト: 在外公館リスト!$A:$B

Sheet 入力
A1: 医薬品購送依頼書 入力シート － ここに入力すると「診断書」「指示書」シートに自動反映されます | P1: =IF(D13="","",DATE(D13,F13,H13))
A2: ※黄色いセルに入力してください。「診断書」「指示書」シートは自動生成されるので直接編集しないでください。 | P2: =IF($P$1="","",EDATE($P$1,3))
P3: =IF(B24<>"","（１）","")&IF(B25<>"","（２）","")&IF(B26<>"","（３）","")&IF(B27<>"","（４）","")&IF(B28<>"","（５）","")&IF(B29<>"","（６）","")&IF(B30<>"","（７）","")&IF(B31<>"","（８）","")&IF(B32<>"","（９）","")&IF(B33<>"","（１０）","")
A4: ■基本情報 | P4: =SUM(I24:I33)
A5: 患者氏名 | D5: 姓 | G5: 名
A6: フリガナ | D6: セイ | G6: メイ
A7: 生年月日（西暦） | E7: 年 | G7: 月 | I7: 日
A8: 職員コード | E8: 続柄
A9: 職員氏名 | D9: 姓 | G9: 名
A10: ■所属（患者所属／医務官所属）※在外公館コードのセルの▼を押すと一覧表から選べます
A11: 患者所属 | C11: 在外公館コード
A12: 医務官所属
A13: 発行日（西暦） | E13: 年 | G13: 月
A14: （発行日は西暦で入力してください。例：2026）
A15: 医務官／健康管理医氏名 | D15: 姓 | G15: 名
A17: ■追加設定
A18: 病名（慢性疾患）※自由入力
A20: 後発医薬品への変更不可
A22: ■服用薬（最大10件・薬品名／含有量／処方日数は自由入力、用法／用量／単位／剤形はプルダウンから選択、1日分使用量は自動計算）
A23: No | B23: 薬品名 | C23: 含有量 | D23: 用法 | E23: 用量 （1回量） | F23: 単位 | G23: 1日分使用量 （自動計算） | H23: 剤形 | I23: 処方日数 （日分）
A24: 1 | G24: =IF(OR(D24="",E24="",F24=""),"",(IFERROR(VALUE(LEFT(SUBSTITUTE(D24,"Ｘ","X"),SEARCH("X",SUBSTITUTE(D24,"Ｘ","X"))-1)),1))*E24&F24) | Q24: =IF(B24="","","（1）"&B24&C24&" "&G24&" "&D24)
A25: 2 | G25: =IF(OR(D25="",E25="",F25=""),"",(IFERROR(VALUE(LEFT(SUBSTITUTE(D25,"Ｘ","X"),SEARCH("X",SUBSTITUTE(D25,"Ｘ","X"))-1)),1))*E25&F25) | Q25: =IF(B25="","","（2）"&B25&C25&" "&G25&" "&D25)
A26: 3 | G26: =IF(OR(D26="",E26="",F26=""),"",(IFERROR(VALUE(LEFT(SUBSTITUTE(D26,"Ｘ","X"),SEARCH("X",SUBSTITUTE(D26,"Ｘ","X"))-1)),1))*E26&F26) | Q26: =IF(B26="","","（3）"&B26&C26&" "&G26&" "&D26)
A27: 4 | G27: =IF(OR(D27="",E27="",F27=""),"",(IFERROR(VALUE(LEFT(SUBSTITUTE(D27,"Ｘ","X"),SEARCH("X",SUBSTITUTE(D27,"Ｘ","X"))-1)),1))*E27&F27) | Q27: =IF(B27="","","（4）"&B27&C27&" "&G27&" "&D27)
A28: 5 | G28: =IF(OR(D28="",E28="",F28=""),"",(IFERROR(VALUE(LEFT(SUBSTITUTE(D28,"Ｘ","X"),SEARCH("X",SUBSTITUTE(D28,"Ｘ","X"))-1)),1))*E28&F28) | Q28: =IF(B28="","","（5）"&B28&C28&" "&G28&" "&D28)
A29: 6 | G29: =IF(OR(D29="",E29="",F29=""),"",(IFERROR(VALUE(LEFT(SUBSTITUTE(D29,"Ｘ","X"),SEARCH("X",SUBSTITUTE(D29,"Ｘ","X"))-1)),1))*E29&F29) | Q29: =IF(B29="","","（6）"&B29&C29&" "&G29&" "&D29)
A30: 7 | G30: =IF(OR(D30="",E30="",F30=""),"",(IFERROR(VALUE(LEFT(SUBSTITUTE(D30,"Ｘ","X"),SEARCH("X",SUBSTITUTE(D30,"Ｘ","X"))-1)),1))*E30&F30) | Q30: =IF(B30="","","（7）"&B30&C30&" "&G30&" "&D30)
A31: 8 | G31: =IF(OR(D31="",E31="",F31=""),"",(IFERROR(VALUE(LEFT(SUBSTITUTE(D31,"Ｘ","X"),SEARCH("X",SUBSTITUTE(D31,"Ｘ","X"))-1)),1))*E31&F31) | Q31: =IF(B31="","","（8）"&B31&C31&" "&G31&" "&D31)
A32: 9 | G32: =IF(OR(D32="",E32="",F32=""),"",(IFERROR(VALUE(LEFT(SUBSTITUTE(D32,"Ｘ","X"),SEARCH("X",SUBSTITUTE(D32,"Ｘ","X"))-1)),1))*E32&F32) | Q32: =IF(B32="","","（9）"&B32&C32&" "&G32&" "&D32)
A33: 10 | G33: =IF(OR(D33="",E33="",F33=""),"",(IFERROR(VALUE(LEFT(SUBSTITUTE(D33,"Ｘ","X"),SEARCH("X",SUBSTITUTE(D33,"Ｘ","X"))-1)),1))*E33&F33) | Q33: =IF(B33="","","（10）"&B33&C33&" "&G33&" "&D33)
A35: ■整合性チェック（自動判定）
A36: ① 基本情報（患者氏名・生年月日・職員コード・職員氏名・所属・発行日）が入力されているか | E36: =IF(AND(E5<>"",H5<>"",D7<>"",E9<>"",H9<>"",D13<>"",D8<>"",D11<>"",D12<>""),"OK","未入力あり（患者氏名／生年月日／発行日／職員コード／職員氏名／患者所属／医務官所属を確認）")
A37: ② 発行日から有効期限（3ヶ月）内か | E37: =IF($P$1="","未入力（発行日）",IF(TODAY()<=$P$2,"OK（有効期限："&TEXT($P$2,"yyyy/mm/dd")&"）","期限切れ（有効期限："&TEXT($P$2,"yyyy/mm/dd")&"）"))
A38: ③ 服用薬が1件以上入力されているか | E38: =IF(COUNTA(B24:B33)>0,"OK","未入力（薬品が1件も入力されていません）")
A39: ④ 入力済みの薬品行に含有量・用法用量・数量・処方日数の抜けがないか | E39: =IF(SUMPRODUCT((B24:B33<>"")*((C24:C33="")+(D24:D33="")+(E24:E33="")+(F24:F33="")+(I24:I33="")))=0,"OK","入力漏れあり（含有量／用法用量／用量／単位／処方日数を確認）")
A40: ⑤ 購送不可の剤形（液体・軟膏・スプレー式・坐薬・冷所品）が含まれていないか | E40: =IF(COUNTIF(H24:H33,"液体")+COUNTIF(H24:H33,"軟膏")+COUNTIF(H24:H33,"スプレー式")+COUNTIF(H24:H33,"坐薬")+COUNTIF(H24:H33,"冷所品")=0,"OK","購送不可の剤形あり（液体／軟膏／スプレー式／坐薬／冷所品は購送不可。吸入薬はガス不使用の喘息用に限り購送可）")
A41: ⑥ 記名押印・署名（医師本人によるご確認をお願いします） | E41: 要人手確認
A43: =IF(COUNTIF(E36:E40,"OK*")=5,"✅ 自動チェック5項目すべてクリア（⑥署名は別途ご確認ください）","⚠ 要確認項目があります（上記①〜⑤をご確認ください）")

Sheet 診断書
A1: （原本は医薬品購送申込時に本省へ送付、写しは患者保管）
A2: 診 断 書
A4: 氏 名 ： | C4: =入力!E5&" "&入力!H5
A5: 職員コード： | C5: =IF(OR(入力!F8="",入力!F8="本人"),入力!D8,入力!D8&"（"&入力!F8&"）")
A6: （館員家族の場合は職員コードに続柄を記入、例：xxxx（妻））
A7: 生年月日 ： | C7: =IF(入力!D7="","",入力!D7&"年"&入力!F7&"月"&入力!H7&"日")
A8: 所 属 ： | C8: =IF(入力!D11="","",IFERROR(MID(入力!D11,FIND(" ",入力!D11)+1,LEN(入力!D11)),IFERROR(VLOOKUP(入力!D11,在外公館リスト,2,FALSE()),"該当コードなし")))
A10: １．病名（慢性疾患）：
A11: =入力!D18
A14: ２．服用薬・処方：
A15: =入力!Q24
A16: =入力!Q25
A17: =入力!Q26
A18: =入力!Q27
A19: =入力!Q28
A20: =入力!Q29
A21: =入力!Q30
A22: =入力!Q31
A23: =入力!Q32
A24: =入力!Q33
A26: =入力!D18&"にて上記２．"&入力!P3&"を服用中であるが、服用にて症状は安定している。今後も上記医薬品の継続投与が必要であるが、成分等含め相当品が任地にて入手が困難であるので、本邦に購送依頼することが必要である。"
A31: =IF(入力!D13=""," 年 月 日",入力!D13&"年"&入力!F13&"月"&入力!H13&"日") | D31: =IF((IF(入力!D12="","",IFERROR(MID(入力!D12,FIND(" ",入力!D12)+1,LEN(入力!D12)),IFERROR(VLOOKUP(入力!D12,在外公館リスト,2,FALSE()),"該当コードなし"))))="","在 館",IF(入力!D12="","",IFERROR(MID(入力!D12,FIND(" ",入力!D12)+1,LEN(入力!D12)),IFERROR(VLOOKUP(入力!D12,在外公館リスト,2,FALSE()),"該当コードなし"))))
A33: 医務官氏名： 印 | D33: （署名押印）
A35: 【注意事項 患者・医師共通】 ※必読※
A36: １．個人用医薬品購送依頼りん請の都度、本「診断書」も添付が必要。
A37: ２．必ず署名押印をすること。
A38: ３．本「診断書」は、福利厚生室にて保管の必要がある。
A39: ４．本「診断書」の有効期限は３ヶ月で、使用回数は１回限り。
A40: ５．向精神薬・睡眠薬は３０日、新薬は１４日の処方日数制限がある。
A41: ６．本診断書原本は、医薬品購送申込時に本省へ送付すること。

Sheet 指示書
A1: 指 示 書
A2: =IF(入力!D13=""," 年 月 日",入力!D13&"年"&入力!F13&"月"&入力!H13&"日") | D2: =IF((IF(入力!D12="","",IFERROR(MID(入力!D12,FIND(" ",入力!D12)+1,LEN(入力!D12)),IFERROR(VLOOKUP(入力!D12,在外公館リスト,2,FALSE()),"該当コードなし"))))="","在 館",IF(入力!D12="","",IFERROR(MID(入力!D12,FIND(" ",入力!D12)+1,LEN(入力!D12)),IFERROR(VLOOKUP(入力!D12,在外公館リスト,2,FALSE()),"該当コードなし"))))
A3: 健康管理医 印 | D3: （署名押印）
A5: =IF((IF(入力!D12="","",IFERROR(MID(入力!D12,FIND(" ",入力!D12)+1,LEN(入力!D12)),IFERROR(VLOOKUP(入力!D12,在外公館リスト,2,FALSE()),"該当コードなし"))))="","在 大使館",IF(入力!D12="","",IFERROR(MID(入力!D12,FIND(" ",入力!D12)+1,LEN(入力!D12)),IFERROR(VLOOKUP(入力!D12,在外公館リスト,2,FALSE()),"該当コードなし"))))
A6: 患者氏名 | C6: =入力!E5&" "&入力!H5
A7: フリガナ | C7: =IF(AND(入力!E6="",入力!H6=""),"",入力!E6&" "&入力!H6)
A8: 生年月日 | C8: =IF(入力!D7="","西暦 年 月 日","西暦"&入力!D7&"年"&入力!F7&"月"&入力!H7&"日")
A10: 上記の者に下記の医薬品の服用を指示します。
A11: 記
A12: 薬品名 | B12: 含有量 | C12: 用法・用量 | E12: １日分使用量
A13: =IF(入力!B24="","（1）","（1） "&入力!B24) | B13: =IF(入力!C24="","",入力!C24) | C13: =IF(入力!D24="","",入力!D24) | E13: =IF(入力!G24="","",入力!G24)
A14: =IF(入力!B25="","（2）","（2） "&入力!B25) | B14: =IF(入力!C25="","",入力!C25) | C14: =IF(入力!D25="","",入力!D25) | E14: =IF(入力!G25="","",入力!G25)
A15: =IF(入力!B26="","（3）","（3） "&入力!B26) | B15: =IF(入力!C26="","",入力!C26) | C15: =IF(入力!D26="","",入力!D26) | E15: =IF(入力!G26="","",入力!G26)
A16: =IF(入力!B27="","（4）","（4） "&入力!B27) | B16: =IF(入力!C27="","",入力!C27) | C16: =IF(入力!D27="","",入力!D27) | E16: =IF(入力!G27="","",入力!G27)
A17: =IF(入力!B28="","（5）","（5） "&入力!B28) | B17: =IF(入力!C28="","",入力!C28) | C17: =IF(入力!D28="","",入力!D28) | E17: =IF(入力!G28="","",入力!G28)
A18: =IF(入力!B29="","（6）","（6） "&入力!B29) | B18: =IF(入力!C29="","",入力!C29) | C18: =IF(入力!D29="","",入力!D29) | E18: =IF(入力!G29="","",入力!G29)
A19: =IF(入力!B30="","（7）","（7） "&入力!B30) | B19: =IF(入力!C30="","",入力!C30) | C19: =IF(入力!D30="","",入力!D30) | E19: =IF(入力!G30="","",入力!G30)
A20: =IF(入力!B31="","（8）","（8） "&入力!B31) | B20: =IF(入力!C31="","",入力!C31) | C20: =IF(入力!D31="","",入力!D31) | E20: =IF(入力!G31="","",入力!G31)
A21: =IF(入力!B32="","（9）","（9） "&入力!B32) | B21: =IF(入力!C32="","",入力!C32) | C21: =IF(入力!D32="","",入力!D32) | E21: =IF(入力!G32="","",入力!G32)
A22: =IF(入力!B33="","（10）","（10） "&入力!B33) | B22: =IF(入力!C33="","",入力!C33) | C22: =IF(入力!D33="","",入力!D33) | E22: =IF(入力!G33="","",入力!G33)
A23: =IF(入力!P4=0," 日分",入力!P4&" 日分（合計）") | E23: =IF(入力!D20="不可","☑ 後発医薬品への変更不可","□ 後発医薬品への変更不可")
A25: 【注意事項 患者・医師共通】 ※必読※
A26: １．「診断書」を基に発給すること（指示書には病名を書かない）。
A27: ２．購送できる医薬品は、錠剤、顆粒、粉末、貼り薬（湿布薬）、喘息用吸入薬（ガス不使用のものに限る）に限る。
A28: ３．液体、軟膏、スプレー式、坐薬、冷所品等は購送不可（吸入薬はガス不使用のものに限り購送可）。
A29: ４．必ず署名押印をすること。
A30: ５．本「指示書」の有効期限は３ヶ月で、使用回数は１回限り。
A31: ６．向精神薬・睡眠薬は３０日、新薬は１４日の処方日数制限がある。
A32: ７．後発医薬品への変更の差し支えがあると判断した場合には、「後発医薬品への変更不可」に「☑」を記載すること。
A33: ８．申込者は申し込み前に必ずオープンシェア福利厚生室HP個人用医薬品利用案内を読み、診断書指示書の内容を自身で確認・理解のうえ申込者自身の手によって９．のとおり手続きを行うこと。
A34: ９．個人用医薬品購送申込書（様式Ａ）に本指示書（様式Ｂ）の「写」及び診断書【指示書に病名記載がないため、病名と服用薬の整合性を確認する必要があることから、診断書が必要】を添付し、封入の上、共済公信にて購送依頼をすること（メールでの申請は一切不可）。
A35: １０．本指示書原本は、在外療養費請求時に本省へ送付すること（それまでは申込者が保管）。

Sheet 入力ガイド
A1: 入力ガイド（このシートは印刷不要）
A3: 項目 | B3: 説明
A4: 全体の仕組み | B4: 「入力」シートに1回入力するだけで「診断書」「指示書」シートに自動反映されます。氏名・生年月日・薬品リストなどの記載ミス・不一致を防ぐため、2つの書類は入力シートを唯一の情報源としています。
A5: 黄色のセル（入力シート） | B5: 記入・入力してください。薬品名・含有量・用法用量・数量・処方日数・病名はすべて自由入力です。剤形／後発医薬品不可／在外公館種別のみプルダウンから選択します。
A6: 病名（慢性疾患） | B6: 薬品からの自動判定は行いません。診断書の「１．病名（慢性疾患）」欄に表示される内容を、この欄に直接入力してください（複数疾患は「、」区切りで入力）。
A7: 薬品名・含有量 | B7: いずれもプルダウンなしの自由入力です。誤字脱字がないか入力後にご確認ください。
A8: 在外公館 | B8: 「患者所属」「医務官所属」それぞれの黄色いセル（在外公館コード）の▼をクリックすると、在外公館コード＋公館名の一覧表（プルダウン）が表示されるので、その中から該当する公館を選んでください。選択すると右側の「公館名」欄に名称が自動表示されます（コード表は「在外公館リスト」シートを参照、申込書と同じ一覧）。診断書の「所属」欄には患者所属の公館名、診断書・指示書の「在○○館」欄には医務官所属の公館名が反映されます。
A9: 生年月日／発行日 | B9: 年・月・日をそれぞれプルダウンから選択してください。生年月日は西暦、発行日は令和年で選びます（西暦への換算は自動計算されます）。
A10: 医務官／健康管理医氏名 | B10: 基本情報の一番下に配置しています。
A11: 用法・用量 | B11: 代表的な服用パターン一覧（29種）からプルダウンで選択します。リストにない場合は「用法用量マスタ」シートのA列末尾に追記すれば選択肢が増えます。
A12: 服用薬（最大10件） | B12: 薬品名・含有量・数量・処方日数は自由入力です。用法・用量／剤形はプルダウンから選択してください。処方日数は各薬品ごとに入力する形にしています。指示書下部の合計日分は、10行分の処方日数を自動で合算して表示します。
A13: ■整合性チェック | B13: 入力シート下部に自動チェック（①〜⑤）と総合判定が表示されます。赤色の項目があれば申込前に確認してください。
A14: ⑤ 剤形チェック | B14: 購送不可（液体・軟膏・スプレー・冷所品・吸入薬）の薬を選ぶと自動で警告されます。
A15: 指示書に病名が出ない理由 | B15: 指示書の注意事項１にある通り、指示書には病名を書かない運用のため、指示書シートには病名を一切表示していません（診断書のみに表示）。

Sheet 日付選択肢
A1: 西暦年（生年月日用） | B1: 令和年（発行日用） | C1: 月 | D1: 日
A2: 1920 | B2: 1 | C2: 1 | D2: 1
A3: 1921 | B3: 2 | C3: 2 | D3: 2
A4: 1922 | B4: 3 | C4: 3 | D4: 3
A5: 1923 | B5: 4 | C5: 4 | D5: 4
A6: 1924 | B6: 5 | C6: 5 | D6: 5
A7: 1925 | B7: 6 | C7: 6 | D7: 6
A8: 1926 | B8: 7 | C8: 7 | D8: 7
A9: 1927 | B9: 8 | C9: 8 | D9: 8
A10: 1928 | B10: 9 | C10: 9 | D10: 9
A11: 1929 | B11: 10 | C11: 10 | D11: 10
A12: 1930 | B12: 11 | C12: 11 | D12: 11
A13: 1931 | B13: 12 | C13: 12 | D13: 12
A14: 1932 | B14: 13 | D14: 13
A15: 1933 | B15: 14 | D15: 14
A16: 1934 | B16: 15 | D16: 15
A17: 1935 | D17: 16
A18: 1936 | D18: 17
A19: 1937 | D19: 18
A20: 1938 | D20: 19
A21: 1939 | D21: 20
A22: 1940 | D22: 21
A23: 1941 | D23: 22
A24: 1942 | D24: 23
A25: 1943 | D25: 24
A26: 1944 | D26: 25
A27: 1945 | D27: 26
A28: 1946 | D28: 27
... A32: 1950 | D32: 31
A33: 1951
A34: 1952
A35: 1953
A36: 1954
A37: 1955
A38: 1956
A39: 1957
A40: 1958
A41: 1959
A42: 1960
A43: 1961
...

Sheet 用法用量マスタ
A1: 用法・用量（選択肢）
A2: 1X朝食後
A3: 1X昼食後
A4: 1X夕食後
A5: 1X朝食前
A6: 1X夕食前
A7: 1X起床時
A8: 1X就寝前（寝る前）
A9: 2X朝夕食後
A10: 2X朝夕食前
A11: 2X朝・昼食後
A12: 2X朝夕食後（12時間毎）
... A29: 朝1回

Sheet 在外公館リスト
A2: 在外公館コード | B2: 在外公館名 | C2: 選択用（コード＋公館名）
A4: 607C | B4: 東南アジア諸国連合日本政府代表部 | C4: =A4&" "&B4 -> 607C 東南アジア諸国連合日本政府代表部
A5: 301C | B5: 国際連合日本政府代表部 | C5: =A5&" "&B5 -> 301C 国際連合日本政府代表部
A6: 302C | B6: 国際民間航空機関日本政府代表部 | C6: =A6&" "&B6 -> 302C 国際民間航空機関日本政府代表部
A7: 501C | B7: 在ウィーン国際機関日本政府代表部 | C7: =A7&" "&B7 -> 501C 在ウィーン国際機関日本政府代表部
A8: 516C | B8: 在ジュネーブ国際機関日本政府代表部 | C8: =A8&" "&B8 -> 516C 在ジュネーブ国際機関日本政府代表部
A9: 590C | B9: 軍縮会議日本政府代表部 | C9: =A9&" "&B9 -> 590C 軍縮会議日本政府代表部
A10: 505C | B10: 経済協力開発機構日本政府代表部 | C10: =A10&" "&B10 -> 505C 経済協力開発機構日本政府代表部
A11: 521C | B11: 欧州連合日本政府代表部 | C11: =A11&" "&B11 -> 521C 欧州連合日本政府代表部
A12: 521Z | B12: 北大西洋条約機構日本政府代表部 | C12: =A12&" "&B12 -> 521Z 北大西洋条約機構日本政府代表部
A13: 505Z | B13: 国際連合教育科学文化機関日本政府代表部 | C13: =A13&" "&B13 -> 505Z 国際連合教育科学文化機関日本政府代表部
A14: 606A | B14: 在インド大使館 | C14: =A14&" "&B14 -> 606A 在インド大使館
A15: 606V | B15: 在ベンガルール領事事務所 | C15: =A15&" "&B15 -> 606V 在ベンガルール領事事務所
... A265: 739A | B265: 在モーリシャス大使館 | C265: =A265&" "&B265 -> 739A 在モーリシャス大使館
